<?xml version="1.0"?>
<robot name="xarm_leap" xmlns:xacro="http://ros.org/wiki/xacro">
    <!-- Insert at the beginning of xarm_device_macro.xacro -->
  <material name="Black">
    <color rgba="0.0 0.0 0.0 1.0"/>
  </material>
  <material name="Red">
    <color rgba="0.8 0.0 0.0 1.0"/>
  </material>
  <material name="White">
    <color rgba="1.0 1.0 1.0 1.0"/>
  </material>
  <material name="Silver">
    <color rgba="0.753 0.753 0.753 1.0"/>
  </material>
  <link name="world"/>
  <joint name="world_joint" type="fixed">
    <parent link="world"/>
    <child link="link_base"/>
    <origin rpy="0 0 0" xyz="0 0 0"/>
  </joint>
  <link name="link_base">
    <inertial>
      <origin rpy="0 0 0" xyz="-0.021131 -0.0016302 0.056488"/>
      <mass value="0.88556"/>
      <inertia ixx="0.0030595" ixy="0.00012259" ixz="-0.00062705" iyy="0.0037783" iyz="0.00027023" izz="0.0020125"/>
    </inertial>
    <visual>
      <geometry>
        <mesh filename="link_base.stl"/>
      </geometry>
      <origin rpy="0 0 0" xyz="0 0 0"/>
      <material name="White"/>
    </visual>
    <collision>
      <geometry>
        <mesh filename="link_base.stl"/>
      </geometry>
      <origin rpy="0 0 0" xyz="0 0 0"/>
    </collision>
  </link>
  <link name="link1">
    <inertial>
      <origin rpy="0 0 0" xyz="-0.0002 0.02905 -0.01233"/>
      <mass value="2.382"/>
      <inertia ixx="0.0056905" ixy="-1.579e-05" ixz="5.125e-06" iyy="0.0049566" iyz="-0.000873378" izz="0.003316654"/>
    </inertial>
    <visual>
      <geometry>
        <mesh filename="link1.stl"/>
      </geometry>
      <origin rpy="0 0 0" xyz="0 0 0"/>
      <material name="White"/>
    </visual>
    <collision>
      <geometry>
        <mesh filename="link1.stl"/>
      </geometry>
      <origin rpy="0 0 0" xyz="0 0 0"/>
    </collision>
  </link>
  <joint name="joint1" type="revolute">
    <origin rpy="0 0 0" xyz="0 0 0.267"/>
    <parent link="link_base"/>
    <child link="link1"/>
    <axis xyz="0 0 1"/>
    <limit effort="50" lower="-6.283185307179586" upper="6.283185307179586" velocity="3.14"/>
    <dynamics damping="10" friction="1"/>
  </joint>
  <link name="link2">
    <inertial>
      <origin rpy="0 0 0" xyz="0.00022 -0.12856 0.01735"/>
      <mass value="1.869"/>
      <inertia ixx="0.0095989" ixy="1.541e-06" ixz="5.56e-06" iyy="0.00382472" iyz="-0.00317156" izz="0.007565669"/>
    </inertial>
    <visual>
      <geometry>
        <mesh filename="link2.stl"/>
      </geometry>
      <origin rpy="0 0 0" xyz="0 0 0"/>
      <material name="White"/>
    </visual>
    <collision>
      <geometry>
        <mesh filename="link2.stl"/>
      </geometry>
      <origin rpy="0 0 0" xyz="0 0 0"/>
    </collision>
  </link>
  <joint name="joint2" type="revolute">
    <origin rpy="-1.5708 0 0" xyz="0 0 0"/>
    <parent link="link1"/>
    <child link="link2"/>
    <axis xyz="0 0 1"/>
    <limit effort="50" lower="-2.059" upper="2.0944" velocity="3.14"/>
    <dynamics damping="10" friction="1"/>
  </joint>
  <link name="link3">
    <inertial>
      <origin rpy="0 0 0" xyz="0.0466 -0.02463 -0.00768"/>
      <mass value="1.6383"/>
      <inertia ixx="0.00310955" ixy="0.00030837" ixz="-0.00058453" iyy="0.00264483" iyz="0.000338893" izz="0.0026624"/>
    </inertial>
    <visual>
      <geometry>
        <mesh filename="link3.stl"/>
      </geometry>
      <origin rpy="0 0 0" xyz="0 0 0"/>
      <material name="White"/>
    </visual>
    <collision>
      <geometry>
        <mesh filename="link3.stl"/>
      </geometry>
      <origin rpy="0 0 0" xyz="0 0 0"/>
    </collision>
  </link>
  <joint name="joint3" type="revolute">
    <origin rpy="1.5708 0 0" xyz="0 -0.293 0"/>
    <parent link="link2"/>
    <child link="link3"/>
    <axis xyz="0 0 1"/>
    <limit effort="30" lower="-6.283185307179586" upper="6.283185307179586" velocity="3.14"/>
    <dynamics damping="5" friction="1"/>
  </joint>
  <link name="link4">
    <inertial>
      <origin rpy="0 0 0" xyz="0.07047 -0.11575 0.012"/>
      <mass value="1.7269"/>
      <inertia ixx="0.005889" ixy="0.00137112" ixz="0.00088143" iyy="0.00359703" iyz="-0.001762155" izz="0.00543244"/>
    </inertial>
    <visual>
      <geometry>
        <mesh filename="link4.stl"/>
      </geometry>
      <origin rpy="0 0 0" xyz="0 0 0"/>
      <material name="White"/>
    </visual>
    <collision>
      <geometry>
        <mesh filename="link4.stl"/>
      </geometry>
      <origin rpy="0 0 0" xyz="0 0 0"/>
    </collision>
  </link>
  <joint name="joint4" type="revolute">
    <origin rpy="1.5708 0 0" xyz="0.0525 0 0"/>
    <parent link="link3"/>
    <child link="link4"/>
    <axis xyz="0 0 1"/>
    <limit effort="30" lower="-0.19198" upper="3.927" velocity="3.14"/>
    <dynamics damping="5" friction="1"/>
  </joint>
  <link name="link5">
    <inertial>
      <origin rpy="0 0 0" xyz="-0.00032 0.01604 -0.026"/>
      <mass value="1.3203"/>
      <inertia ixx="0.00534665" ixy="1.5117e-05" ixz="-3.69e-07" iyy="0.0049779" iyz="-0.00022132" izz="0.0013624"/>
    </inertial>
    <visual>
      <geometry>
        <mesh filename="link5.stl"/>
      </geometry>
      <origin rpy="0 0 0" xyz="0 0 0"/>
      <material name="White"/>
    </visual>
    <collision>
      <geometry>
        <mesh filename="link5.stl"/>
      </geometry>
      <origin rpy="0 0 0" xyz="0 0 0"/>
    </collision>
  </link>
  <joint name="joint5" type="revolute">
    <origin rpy="1.5708 0 0" xyz="0.0775 -0.3425 0"/>
    <parent link="link4"/>
    <child link="link5"/>
    <axis xyz="0 0 1"/>
    <limit effort="30" lower="-6.283185307179586" upper="6.283185307179586" velocity="3.14"/>
    <dynamics damping="5" friction="1"/>
  </joint>
  <link name="link6">
    <inertial>
      <origin rpy="0 0 0" xyz="0.06469 0.03278 0.02141"/>
      <mass value="1.325"/>
      <inertia ixx="0.0014745" ixy="-0.000488" ixz="0.0002953" iyy="0.0019037" iyz="0.00014749" izz="0.0023652"/>
    </inertial>
    <visual>
      <geometry>
        <mesh filename="link6.stl"/>
      </geometry>
      <origin rpy="0 0 0" xyz="0 0 0"/>
      <material name="White"/>
    </visual>
    <collision>
      <geometry>
        <mesh filename="link6.stl"/>
      </geometry>
      <origin rpy="0 0 0" xyz="0 0 0"/>
    </collision>
  </link>
  <joint name="joint6" type="revolute">
    <origin rpy="1.5708 0 0" xyz="0 0 0"/>
    <parent link="link5"/>
    <child link="link6"/>
    <axis xyz="0 0 1"/>
    <limit effort="20" lower="-1.69297" upper="3.141592653589793" velocity="3.14"/>
    <dynamics damping="2" friction="1"/>
  </joint>
  <link name="link7">
    <inertial>
      <origin rpy="0 0 0" xyz="0 -0.00677 -0.01098"/>
      <mass value="0.17"/>
      <inertia ixx="9.3e-05" ixy="-0.0" ixz="-0.0" iyy="5.87e-05" iyz="-3.6e-06" izz="0.000132"/>
    </inertial>
    <visual>
      <geometry>
        <mesh filename="link7.stl"/>
      </geometry>
      <origin rpy="0 0 0" xyz="0 0 0"/>
      <material name="Silver"/>
    </visual>
    <collision>
      <geometry>
        <mesh filename="end_tool.stl"/>
      </geometry>
      <origin rpy="0 0 0" xyz="0 0 0"/>
    </collision>
  </link>
  <joint name="joint7" type="revolute">
    <origin rpy="-1.5708 0 0" xyz="0.076 0.097 0"/>
    <parent link="link6"/>
    <child link="link7"/>
    <axis xyz="0 0 1"/>
    <limit effort="20" lower="-6.283185307179586" upper="6.283185307179586" velocity="3.14"/>
    <dynamics damping="2" friction="1"/>
  </joint>
  <!-- <link name="${prefix}link_eef" />
    <joint name="${prefix}joint_eef" type="fixed">
      <origin xyz="0 0 0" rpy="0 0 0" />
      <parent link="${prefix}link7" />
      <child link="${prefix}link_eef" />
    </joint> -->
  <transmission name="tran1">
    <type>transmission_interface/SimpleTransmission</type>
    <joint name="joint1">
      <hardwareInterface>hardware_interface/PositionJointInterface</hardwareInterface>
    </joint>
    <actuator name="motor1">
      <hardwareInterface>hardware_interface/PositionJointInterface</hardwareInterface>
      <mechanicalReduction>100</mechanicalReduction>
    </actuator>
  </transmission>
  <transmission name="tran2">
    <type>transmission_interface/SimpleTransmission</type>
    <joint name="joint2">
      <hardwareInterface>hardware_interface/PositionJointInterface</hardwareInterface>
    </joint>
    <actuator name="motor2">
      <hardwareInterface>hardware_interface/PositionJointInterface</hardwareInterface>
      <mechanicalReduction>100</mechanicalReduction>
    </actuator>
  </transmission>
  <transmission name="tran3">
    <type>transmission_interface/SimpleTransmission</type>
    <joint name="joint3">
      <hardwareInterface>hardware_interface/PositionJointInterface</hardwareInterface>
    </joint>
    <actuator name="motor3">
      <hardwareInterface>hardware_interface/PositionJointInterface</hardwareInterface>
      <mechanicalReduction>100</mechanicalReduction>
    </actuator>
  </transmission>
  <transmission name="tran4">
    <type>transmission_interface/SimpleTransmission</type>
    <joint name="joint4">
      <hardwareInterface>hardware_interface/PositionJointInterface</hardwareInterface>
    </joint>
    <actuator name="motor4">
      <hardwareInterface>hardware_interface/PositionJointInterface</hardwareInterface>
      <mechanicalReduction>100</mechanicalReduction>
    </actuator>
  </transmission>
  <transmission name="tran5">
    <type>transmission_interface/SimpleTransmission</type>
    <joint name="joint5">
      <hardwareInterface>hardware_interface/PositionJointInterface</hardwareInterface>
    </joint>
    <actuator name="motor5">
      <hardwareInterface>hardware_interface/PositionJointInterface</hardwareInterface>
      <mechanicalReduction>100</mechanicalReduction>
    </actuator>
  </transmission>
  <transmission name="tran6">
    <type>transmission_interface/SimpleTransmission</type>
    <joint name="joint6">
      <hardwareInterface>hardware_interface/PositionJointInterface</hardwareInterface>
    </joint>
    <actuator name="motor6">
      <hardwareInterface>hardware_interface/PositionJointInterface</hardwareInterface>
      <mechanicalReduction>100</mechanicalReduction>
    </actuator>
  </transmission>
  <transmission name="tran7">
    <type>transmission_interface/SimpleTransmission</type>
    <joint name="joint7">
      <hardwareInterface>hardware_interface/PositionJointInterface</hardwareInterface>
    </joint>
    <actuator name="motor7">
      <hardwareInterface>hardware_interface/PositionJointInterface</hardwareInterface>
      <mechanicalReduction>100</mechanicalReduction>
    </actuator>
  </transmission>
  <gazebo reference="link_base">
    <selfCollide>true</selfCollide>
  </gazebo>
  <gazebo reference="link1">
    <selfCollide>true</selfCollide>
  </gazebo>
  <gazebo reference="link2">
    <selfCollide>true</selfCollide>
  </gazebo>
  <gazebo reference="link3">
    <selfCollide>true</selfCollide>
  </gazebo>
  <gazebo reference="link4">
    <selfCollide>true</selfCollide>
  </gazebo>
  <gazebo reference="link5">
    <selfCollide>true</selfCollide>
  </gazebo>
  <gazebo reference="link6">
    <selfCollide>true</selfCollide>
  </gazebo>
  <gazebo reference="link7">
    <selfCollide>true</selfCollide>
  </gazebo>
  <!-- Force-Torque Sensor (Dummy Link) -->
  <link name="dummy_ft_sensor">
    <visual name="ft_sensor_visual">
      <origin xyz="0 0 0" rpy="0 0 0"/>
      <geometry>
        <cylinder radius="0.04" length="0.06"/>
      </geometry>
      <material name="White">
        <color rgba="1.0 1.0 1.0 1.0"/>
      </material>
    </visual>
    <collision name="ft_sensor_collision">
      <origin xyz="0 0 0" rpy="0 0 0"/>
      <geometry>
        <cylinder radius="0.04" length="0.06"/>
      </geometry>
    </collision>
  </link>
  <link name="link_eef"/>
  <joint name="joint_eef" type="fixed">
    <origin rpy="0 0 0" xyz="0 0 0"/>
    <parent link="link7"/>
    <child link="link_eef"/>
  </joint>
  <!-- link_eef -> dummy_ft_sensor -->
  <joint name="joint_ft_sensor" type="fixed">
    <origin xyz="0 0 0.028" rpy="0 0 0"/>
    <parent link="link_eef"/>
    <child link="dummy_ft_sensor"/>
  </joint>
  <gazebo>
    <plugin filename="libgazebo_ros_control.so" name="gazebo_ros_control">
      <!-- <controlPeriod>0.0001</controlPeriod> -->
      <legacyModeNS>true</legacyModeNS>
      <!-- <preserveWorldVelocity>true</preserveWorldVelocity> -->
    </plugin>
  </gazebo>
  <!-- Insert at the end of xarm_device_macro.xacro -->

  
  <!-- Fixed joint to attach Leap Hand to xArm link_eef -->
  <joint name="xarm7_to_leap_hand" type="fixed">
    <parent link="dummy_ft_sensor"/>
    <child link="palm_lower"/>
    <origin xyz="0.06 -0.035 0.04" rpy="3.1416 0 0"/>
  </joint>

  <link name="palm_lower">
<visual>
<origin xyz="-0.020095249652862544332 0.025757756134899473244 -0.034722403578460216134" rpy="0 -0 0" />
<geometry>
<mesh filename="palm_lower.stl"/>
</geometry>
<material name="palm_lower_material">
<color rgba="0.60392156862745094426 0.14901960784313725283 0.14901960784313725283 1.0"/>
</material>
</visual>
<collision>
<origin xyz="-0.020095249652862544332 0.025757756134899473244 -0.034722403578460216134" rpy="0 -0 0" />
<geometry>
<mesh filename="palm_lower.stl"/>
</geometry>
</collision>
<inertial>
<origin xyz="0 0 0" rpy="0 0 0"/>
<mass value="0.237" />
<inertia ixx="0.000354094" ixy="-0.000001193"  ixz="-0.000002445" iyy="0.000260915" iyz="-0.000002905" izz="0.000529257" />
</inertial>
</link>

<link name="mcp_joint">
<visual>
<origin xyz="0.0084069022611744960438 0.0077662438597169954416 0.014657354985032912051" rpy="1.6375789613220999807e-15 -1.0210473302491019535e-30 1.7177968783327987474e-31" />
<geometry>
<mesh filename="mcp_joint.stl"/>
</geometry>
<material name="mcp_joint_material">
<color rgba="0.86666666666666669627 0.86666666666666669627 0.050980392156862744391 1.0"/>
</material>
</visual>
<collision>
<origin xyz="0.0084069022611744960438 0.0077662438597169954416 0.014657354985032912051" rpy="1.6375789613220999807e-15 -1.0210473302491019535e-30 1.7177968783327987474e-31" />
<geometry>
<mesh filename="mcp_joint.stl"/>
</geometry>
</collision>
<inertial>
<origin xyz="0 0 0" rpy="0 0 0"/>
<mass value="0.044" />
<inertia ixx="0.000011499" ixy="0.000003049"  ixz="0.000000121" iyy="0.000007796" iyz="0.000000112" izz="0.000014759" />
</inertial>
</link>

<link name="pip">
<visual>
<origin xyz="0.0096433630922713280131 0.00029999999999998951117 0.00078403401041737645627" rpy="-1.570796326794896558 -1.570796326794896336 0" />
<geometry>
<mesh filename="pip.stl"/>
</geometry>
<material name="pip_material">
<color rgba="0.74901960784313725839 0.74901960784313725839 0.74901960784313725839 1.0"/>
</material>
</visual>
<collision>
<origin xyz="0.0096433630922713280131 0.00029999999999998951117 0.00078403401041737645627" rpy="-1.570796326794896558 -1.570796326794896336 0" />
<geometry>
<mesh filename="pip.stl"/>
</geometry>
</collision>
<inertial>
<origin xyz="0 0 0" rpy="0 0 0"/>
<mass value="0.032" />
<inertia ixx="0.000004798" ixy="0.000000012"  ixz="0.000000004" iyy="0.000002862" iyz="0.000000011" izz="0.000004234" />
</inertial>
</link>

<link name="dip">
<visual>
<origin xyz="0.021133352895225002849 -0.0084321191467048792201 0.0097850881620952408213" rpy="-3.141592653589793116 4.5075111242164408299e-32 4.4395481053923607589e-32" />
<geometry>
<mesh filename="dip.stl"/>
</geometry>
<material name="dip_material">
<color rgba="0.86666666666666669627 0.86666666666666669627 0.050980392156862744391 1.0"/>
</material>
</visual>
<collision>
<origin xyz="0.021133352895225002849 -0.0084321191467048792201 0.0097850881620952408213" rpy="-3.141592653589793116 4.5075111242164408299e-32 4.4395481053923607589e-32" />
<geometry>
<mesh filename="dip.stl"/>
</geometry>
</collision>
<inertial>
<origin xyz="0 0 0" rpy="0 0 0"/>
<mass value="0.037" />
<inertia ixx="0.000005542" ixy="-0.000000607"  ixz="-0.000000017" iyy="0.000005727" iyz="-0.000000023" izz="0.000006682" />
</inertial>
</link>

<link name="fingertip">
<visual>
<origin xyz="0.013286424108533503169 -0.0061142383865419869249 0.014499999999999497666" rpy="3.141592653589793116 1.1993117970061734707e-33 4.4395481053923607589e-32" />
<geometry>
<mesh filename="fingertip.stl"/>
</geometry>
<material name="fingertip_material">
<color rgba="0.86666666666666669627 0.86666666666666669627 0.050980392156862744391 1.0"/>
</material>
</visual>
<collision>
<origin xyz="0.013286424108533503169 -0.0061142383865419869249 0.014499999999999497666" rpy="3.141592653589793116 1.1993117970061734707e-33 4.4395481053923607589e-32" />
<geometry>
<mesh filename="fingertip.stl"/>
</geometry>
</collision>
<inertial>
<origin xyz="0 0 0" rpy="0 0 0"/>
<mass value="0.016" />
<inertia ixx="0.000003368" ixy="0.000000115"  ixz="0" iyy="0.000001556" iyz="0" izz="0.000002863" />
</inertial>
</link>

<joint name="0" type="revolute">
<origin xyz="-0.012200000000000007713 0.038099999999999994982 0.014500000000000000736" rpy="-1.570796326794896558 -1.0065212660796336576e-15 1.5707963267948943376" />
<parent link="mcp_joint" />
<child link="pip" />
<axis xyz="0 0 -1"/>
<limit effort="0.95" velocity="8.48" lower = "-1.047" upper = "1.047"/>
<joint_properties friction="0.0"/>
</joint>

<joint name="1" type="revolute">
<origin xyz="-0.0070952496528625457958 0.023057756134899472233 -0.01872240357846021927" rpy="1.5707963267948950037 1.5707963267948945596 0" />
<parent link="palm_lower" />
<child link="mcp_joint" />
<axis xyz="0 0 -1"/>
<limit effort="0.95" velocity="8.48" lower = "-0.314" upper = "2.23"/>
<joint_properties friction="0.0"/>
</joint>

<joint name="2" type="revolute">
<origin xyz="0.01499999999999996822 0.014299999999999904801 -0.012999999999999824196" rpy="1.5707963267948958919 -1.570796326794896336 0" />
<parent link="pip" />
<child link="dip" />
<axis xyz="0 0 -1"/>
<limit effort="0.95" velocity="8.48" lower = "-0.506" upper = "1.885"/>  
<joint_properties friction="0.0"/>
</joint>

<joint name="3" type="revolute">
<origin xyz="-4.0880582495572692636e-09 -0.036100004210367367397 0.00020000000000007858714" rpy="4.5935029425113685044e-17 -2.8730071914463794583e-16 4.4395481053923607589e-32" />
<parent link="dip" />
<child link="fingertip" />
<axis xyz="0 0 -1"/>
<limit effort="0.95" velocity="8.48" lower = "-0.366" upper = "2.042"/>   
<joint_properties friction="0.0"/>
</joint>

<link name="mcp_joint_2">
<visual>
<origin xyz="0.0084069022611744960438 0.0077662438597169954416 0.014657354985032913786" rpy="1.6375789613220999807e-15 -1.0076465469034000467e-30 2.1209300131419907151e-61" />
<geometry>
<mesh filename="mcp_joint.stl"/>
</geometry>
<material name="mcp_joint_material">
<color rgba="0.86666666666666669627 0.86666666666666669627 0.050980392156862744391 1.0"/>
</material>
</visual>
<collision>
<origin xyz="0.0084069022611744960438 0.0077662438597169954416 0.014657354985032913786" rpy="1.6375789613220999807e-15 -1.0076465469034000467e-30 2.1209300131419907151e-61" />
<geometry>
<mesh filename="mcp_joint.stl"/>
</geometry>
</collision>
<inertial>
<origin xyz="0 0 0" rpy="0 0 0"/>
<mass value="0.044" />
<inertia ixx="0.000011499" ixy="0.000003049"  ixz="0.000000121" iyy="0.000007796" iyz="0.000000112" izz="0.000014759" />
</inertial>
</link>

<link name="pip_2">
<visual>
<origin xyz="0.0096433630922713280131 0.00029999999999999471534 0.00078403401041737645627" rpy="-1.570796326794896558 -1.570796326794896336 0" />
<geometry>
<mesh filename="pip.stl"/>
</geometry>
<material name="pip_material">
<color rgba="0.74901960784313725839 0.74901960784313725839 0.74901960784313725839 1.0"/>
</material>
</visual>
<collision>
<origin xyz="0.0096433630922713280131 0.00029999999999999471534 0.00078403401041737645627" rpy="-1.570796326794896558 -1.570796326794896336 0" />
<geometry>
<mesh filename="pip.stl"/>
</geometry>
</collision>
<inertial>
<origin xyz="0 0 0" rpy="0 0 0"/>
<mass value="0.032" />
<inertia ixx="0.000004798" ixy="0.000000012"  ixz="0.000000004" iyy="0.000002862" iyz="0.000000011" izz="0.000004234" />
</inertial>
</link>

<link name="dip_2">
<visual>
<origin xyz="0.021133352895225002849 -0.0084321191467048653423 0.0097850881620952373519" rpy="-3.141592653589793116 2.1146933785271955805e-32 1.4408183216511868558e-31" />
<geometry>
<mesh filename="dip.stl"/>
</geometry>
<material name="dip_material">
<color rgba="0.86666666666666669627 0.86666666666666669627 0.050980392156862744391 1.0"/>
</material>
</visual>
<collision>
<origin xyz="0.021133352895225002849 -0.0084321191467048653423 0.0097850881620952373519" rpy="-3.141592653589793116 2.1146933785271955805e-32 1.4408183216511868558e-31" />
<geometry>
<mesh filename="dip.stl"/>
</geometry>
</collision>
<inertial>
<origin xyz="0 0 0" rpy="0 0 0"/>
<mass value="0.037" />
<inertia ixx="0.000005542" ixy="-0.000000607"  ixz="-0.000000017" iyy="0.000005727" iyz="-0.000000023" izz="0.000006682" />
</inertial>
</link>

<link name="fingertip_2">
<visual>
<origin xyz="0.01328642410853349623 -0.0061142383865420008027 0.014499999999999495931" rpy="3.141592653589793116 -4.3179597882835943107e-33 1.4408183216511868558e-31" />
<geometry>
<mesh filename="fingertip.stl"/>
</geometry>
<material name="fingertip_material">
<color rgba="0.86666666666666669627 0.86666666666666669627 0.050980392156862744391 1.0"/>
</material>
</visual>
<collision>
<origin xyz="0.01328642410853349623 -0.0061142383865420008027 0.014499999999999495931" rpy="3.141592653589793116 -4.3179597882835943107e-33 1.4408183216511868558e-31" />
<geometry>
<mesh filename="fingertip.stl"/>
</geometry>
</collision>
<inertial>
<origin xyz="0 0 0" rpy="0 0 0"/>
<mass value="0.016" />
<inertia ixx="0.000003368" ixy="0.000000115"  ixz="0" iyy="0.000001556" iyz="0" izz="0.000002863" />
</inertial>
</link>

<joint name="4" type="revolute">
<origin xyz="-0.012200000000000019856 0.038099999999999981104 0.01450000000000000594" rpy="-1.570796326794896558 -1.0065212760057939085e-15 1.5707963267948943376" />
<parent link="mcp_joint_2" />
<child link="pip_2" />
<axis xyz="0 0 -1"/>
<limit effort="0.95" velocity="8.48" lower = "-1.047" upper = "1.047"/>
<joint_properties friction="0.0"/>
</joint>

<joint name="5" type="revolute">
<origin xyz="-0.0070952496528625388569 -0.022392243865100525113 -0.018722403578460229678" rpy="1.570796326794896558 1.570796326794896558 0" />
<parent link="palm_lower" />
<child link="mcp_joint_2" />
<axis xyz="0 0 -1"/>
<limit effort="0.95" velocity="8.48" lower = "-0.314" upper = "2.23"/>
<joint_properties friction="0.0"/>
</joint>

<joint name="6" type="revolute">
<origin xyz="0.014999999999999975159 0.014300000000000000211 -0.013000000000000018485" rpy="1.5707963267948958919 -1.570796326794896336 0" />
<parent link="pip_2" />
<child link="dip_2" />
<axis xyz="0 0 -1"/>
<limit effort="0.95" velocity="8.48" lower = "-0.506" upper = "1.885"/>  
<joint_properties friction="0.0"/>
</joint>

<joint name="7" type="revolute">
<origin xyz="1.0061396160665481148e-16 -0.036099999999999854428 0.00020000000000007858714" rpy="4.5935029425113654229e-17 -2.8730071914463794583e-16 1.4408183216511868558e-31" />
<parent link="dip_2" />
<child link="fingertip_2" />
<axis xyz="0 0 -1"/>
<limit effort="0.95" velocity="8.48" lower = "-0.366" upper = "2.042"/>   
<joint_properties friction="0.0"/>
</joint>

<link name="mcp_joint_3">
<visual>
<origin xyz="0.0084069022611744995133 0.0077662438597169963089 0.014657354985032913786" rpy="1.6375789613220999807e-15 -1.0059504988632626953e-30 5.729641584552035421e-32" />
<geometry>
<mesh filename="mcp_joint.stl"/>
</geometry>
<material name="mcp_joint_material">
<color rgba="0.86666666666666669627 0.86666666666666669627 0.050980392156862744391 1.0"/>
</material>
</visual>
<collision>
<origin xyz="0.0084069022611744995133 0.0077662438597169963089 0.014657354985032913786" rpy="1.6375789613220999807e-15 -1.0059504988632626953e-30 5.729641584552035421e-32" />
<geometry>
<mesh filename="mcp_joint.stl"/>
</geometry>
</collision>
<inertial>
<origin xyz="0 0 0" rpy="0 0 0"/>
<mass value="0.044" />
<inertia ixx="0.000011499" ixy="0.000003049"  ixz="0.000000121" iyy="0.000007796" iyz="0.000000112" izz="0.000014759" />
</inertial>
</link>

<link name="pip_3">
<visual>
<origin xyz="0.0096433630922713314826 0.00029999999999998083755 0.00078403401041737645627" rpy="-1.570796326794896558 -1.570796326794896336 0" />
<geometry>
<mesh filename="pip.stl"/>
</geometry>
<material name="pip_material">
<color rgba="0.74901960784313725839 0.74901960784313725839 0.74901960784313725839 1.0"/>
</material>
</visual>
<collision>
<origin xyz="0.0096433630922713314826 0.00029999999999998083755 0.00078403401041737645627" rpy="-1.570796326794896558 -1.570796326794896336 0" />
<geometry>
<mesh filename="pip.stl"/>
</geometry>
</collision>
<inertial>
<origin xyz="0 0 0" rpy="0 0 0"/>
<mass value="0.032" />
<inertia ixx="0.000004798" ixy="0.000000012"  ixz="0.000000004" iyy="0.000002862" iyz="0.000000011" izz="0.000004234" />
</inertial>
</link>

<link name="dip_3">
<visual>
<origin xyz="0.021133352895225006318 -0.0084321191467048653423 0.0097850881620952373519" rpy="-3.141592653589793116 -1.4095651113919093005e-33 1.5565411607615035382e-32" />
<geometry>
<mesh filename="dip.stl"/>
</geometry>
<material name="dip_material">
<color rgba="0.86666666666666669627 0.86666666666666669627 0.050980392156862744391 1.0"/>
</material>
</visual>
<collision>
<origin xyz="0.021133352895225006318 -0.0084321191467048653423 0.0097850881620952373519" rpy="-3.141592653589793116 -1.4095651113919093005e-33 1.5565411607615035382e-32" />
<geometry>
<mesh filename="dip.stl"/>
</geometry>
</collision>
<inertial>
<origin xyz="0 0 0" rpy="0 0 0"/>
<mass value="0.037" />
<inertia ixx="0.000005542" ixy="-0.000000607"  ixz="-0.000000017" iyy="0.000005727" iyz="-0.000000023" izz="0.000006682" />
</inertial>
</link>

<link name="fingertip_3">
<visual>
<origin xyz="0.013286424108533501434 -0.0061142383865419869249 0.0144999999999994994" rpy="3.141592653589793116 8.6170716950575402125e-33 1.5565411607615035382e-32" />
<geometry>
<mesh filename="fingertip.stl"/>
</geometry>
<material name="fingertip_material">
<color rgba="0.86666666666666669627 0.86666666666666669627 0.050980392156862744391 1.0"/>
</material>
</visual>
<collision>
<origin xyz="0.013286424108533501434 -0.0061142383865419869249 0.0144999999999994994" rpy="3.141592653589793116 8.6170716950575402125e-33 1.5565411607615035382e-32" />
<geometry>
<mesh filename="fingertip.stl"/>
</geometry>
</collision>
<inertial>
<origin xyz="0 0 0" rpy="0 0 0"/>
<mass value="0.016" />
<inertia ixx="0.000003368" ixy="0.000000115"  ixz="0" iyy="0.000001556" iyz="0" izz="0.000002863" />
</inertial>
</link>

<joint name="8" type="revolute">
<origin xyz="-0.012200000000000004244 0.038100000000000001921 0.014499999999999999001" rpy="-1.570796326794896558 -1.0065212660796360242e-15 1.5707963267948943376" />
<parent link="mcp_joint_3" />
<child link="pip_3" />
<axis xyz="0 0 -1"/>
<limit effort="0.95" velocity="8.48" lower = "-1.047" upper = "1.047"/>
<joint_properties friction="0.0"/>
</joint>

<joint name="9" type="revolute">
<origin xyz="-0.0070952454426398371343 -0.067842243865100515521 -0.018722407666402932774" rpy="1.5707963267948950037 1.5707963267948945596 0" />
<parent link="palm_lower" />
<child link="mcp_joint_3" />
<axis xyz="0 0 -1"/>
<limit effort="0.95" velocity="8.48" lower = "-0.314" upper = "2.23"/>
<joint_properties friction="0.0"/>
</joint>

<joint name="10" type="revolute">
<origin xyz="0.014999999999999971689 0.014299999999999951639 -0.012999999999999959505" rpy="1.5707963267948958919 -1.570796326794896336 0" />
<parent link="pip_3" />
<child link="dip_3" />
<axis xyz="0 0 -1"/>
<limit effort="0.95" velocity="8.48" lower = "-0.506" upper = "1.885"/>  
<joint_properties friction="0.0"/>
</joint>

<joint name="11" type="revolute">
<origin xyz="9.7144514654701197287e-17 -0.036099999999999868305 0.00020000000000007511769" rpy="4.5935029425113685044e-17 -2.8730071914463799514e-16 1.5565411607615035382e-32" />
<parent link="dip_3" />
<child link="fingertip_3" />
<axis xyz="0 0 -1"/>
<limit effort="0.95" velocity="8.48" lower = "-0.366" upper = "2.042"/>   
<joint_properties friction="0.0"/>
</joint>

<link name="pip_4">
<visual>
<origin xyz="-0.0053566369077286714317 0.00029999999999999991951 0.00078403401041737819099" rpy="-1.570796326794896558 -1.570796326794896336 0" />
<geometry>
<mesh filename="pip.stl"/>
</geometry>
<material name="pip_material">
<color rgba="0.74901960784313725839 0.74901960784313725839 0.74901960784313725839 1.0"/>
</material>
</visual>
<collision>
<origin xyz="-0.0053566369077286714317 0.00029999999999999991951 0.00078403401041737819099" rpy="-1.570796326794896558 -1.570796326794896336 0" />
<geometry>
<mesh filename="pip.stl"/>
</geometry>
</collision>
<inertial>
<origin xyz="0 0 0" rpy="0 0 0"/>
<mass value="0.032" />
<inertia ixx="0.000004798" ixy="0.000000012"  ixz="0.000000004" iyy="0.000002862" iyz="0.000000011" izz="0.000004234" />
</inertial>
</link>

<link name="thumb_pip">
<visual>
<origin xyz="0.011961920770611186859 -5.3082538364890297089e-16 -0.015852648956664199681" rpy="1.570796326794896558 1.6050198443300152637e-46 -3.9204996250525192755e-59" />
<geometry>
<mesh filename="thumb_pip.stl"/>
</geometry>
<material name="thumb_pip_material">
<color rgba="0.86666666666666669627 0.86666666666666669627 0.050980392156862744391 1.0"/>
</material>
</visual>
<collision>
<origin xyz="0.011961920770611186859 -5.3082538364890297089e-16 -0.015852648956664199681" rpy="1.570796326794896558 1.6050198443300152637e-46 -3.9204996250525192755e-59" />
<geometry>
<mesh filename="thumb_pip.stl"/>
</geometry>
</collision>
<inertial>
<origin xyz="0 0 0" rpy="0 0 0"/>
<mass value="0.003" />
<inertia ixx="0.000000593" ixy="0"  ixz="0" iyy="0.000000549" iyz="0" izz="0.000000224" />
</inertial>
</link>

<link name="thumb_dip">
<visual>
<origin xyz="0.043968715707239175439 0.057952952973709198625 -0.0086286764493694757122" rpy="1.9428902930940098942e-16 3.2751579226442200773e-15 1.1123758529657360012e-46" />
<geometry>
<mesh filename="thumb_dip.stl"/>
</geometry>
<material name="thumb_dip_material">
<color rgba="0.86666666666666669627 0.86666666666666669627 0.050980392156862744391 1.0"/>
</material>
</visual>
<collision>
<origin xyz="0.043968715707239175439 0.057952952973709198625 -0.0086286764493694757122" rpy="1.9428902930940098942e-16 3.2751579226442200773e-15 1.1123758529657360012e-46" />
<geometry>
<mesh filename="thumb_dip.stl"/>
</geometry>
</collision>
<inertial>
<origin xyz="0 0 0" rpy="0 0 0"/>
<mass value="0.038" />
<inertia ixx="0.000008474" ixy="0.000000241"  ixz="0.000000026" iyy="0.000003841" iyz="0.000000025" izz="0.000007679" />
</inertial>
</link>

<link name="thumb_fingertip">
<visual>
<origin xyz="0.062559538462667388381 0.078459682911396988469 0.048992911807332215068" rpy="4.3790577010156367543e-47 -3.3306690738754701143e-16 1.2042408677791935383e-46" />
<geometry>
<mesh filename="thumb_fingertip.stl"/>
</geometry>
<material name="thumb_fingertip_material">
<color rgba="0.60392156862745094426 0.14901960784313725283 0.14901960784313725283 1.0"/>
</material>
</visual>
<collision>
<origin xyz="0.062559538462667388381 0.078459682911396988469 0.048992911807332215068" rpy="4.3790577010156367543e-47 -3.3306690738754701143e-16 1.2042408677791935383e-46" />
<geometry>
<mesh filename="thumb_fingertip.stl"/>
</geometry>
</collision>
<inertial>
<origin xyz="0 0 0" rpy="0 0 0"/>
<mass value="0.049" />
<inertia ixx="0.000020372" ixy="-0.000000489"  ixz="-0.00000003" iyy="0.000004336" iyz="-0.000000097" izz="0.000019845" />
</inertial>
</link>

<joint name="12" type="revolute">
<origin xyz="-0.069395249652862533996 -0.0012422438651005258004 -0.021622403578460215601" rpy="-8.2381766464939424156e-17 1.5707963267948956698 0" />
<parent link="palm_lower" />
<child link="pip_4" />
<axis xyz="0 0 -1"/>
<limit effort="0.95" velocity="8.48" lower = "-0.349" upper = "2.094"/> 
<joint_properties friction="0.0"/>
</joint>

<joint name="13" type="revolute">
<origin xyz="-2.7755575615628913511e-17 0.014300000000000005415 -0.013000000000000011546" rpy="1.5707963267948958919 -1.570796326794896336 0" />
<parent link="pip_4" />
<child link="thumb_pip" />
<axis xyz="0 0 -1"/>
<limit effort="0.95" velocity="8.48" lower = "-0.47" upper = "2.443"/> 
<joint_properties friction="0.0"/>
</joint>

<joint name="14" type="revolute">
<origin xyz="0 0.014499999999999966041 -0.017000000000000053263" rpy="-1.570796326794896558 1.6050198443300131245e-46 -1.9721522630516624601e-31" />
<parent link="thumb_pip" />
<child link="thumb_dip" />
<axis xyz="0 0 -1"/>
<limit effort="0.95" velocity="8.48" lower = "-1.20" upper = "1.90"/> 
<joint_properties friction="0.0"/>
</joint>

<joint name="15" type="revolute">
<origin xyz="-1.249000902703301108e-16 0.046599999999999863753 0.00019999999999997710581" rpy="1.5063958491491781023e-44 5.4234187233935260503e-31 3.141592653589793116" />
<parent link="thumb_dip" />
<child link="thumb_fingertip" />
<axis xyz="0 0 -1"/>
<limit effort="0.95" velocity="8.48" lower = "-1.34" upper = "1.88"/> 
<joint_properties friction="0.0"/>
</joint>

</robot>
